Workbook

Sheet Summary
A1: SmartDEV Validation Rules
A2: Schema-aligned validation inventory with executable Spark SQL predicates and clearly isolated review exceptions.
A4: Domain | B4: Domain-tab rules | C4: Structural | D4: Business | E4: SQL ready | F4: Custom Logic in Spark | G4: Json validation | H4: Discarded | I4: Needs discussion | J4: Moved to Reviewed | K4: Review focus
A5: Person | B5: =COUNTA(Person!$C$2:$C$1007) -> 193 | C5: =COUNTIF(Person!$G$2:$G$1007,"STRUCTURAL") -> 187 | D5: =COUNTIF(Person!$G$2:$G$1007,"BUSINESS") -> 6 | E5: =COUNTIF(Person!$L$2:$L$1007,"SQL READY") -> 55 | F5: =COUNTIF(Person!$L$2:$L$1007,"CUSTOM LOGIC") -> 3 | G5: =COUNTIF(Person!$L$2:$L$1007,"HANDLED IN JSON VALIDATION") -> 62 | H5: =COUNTIF(Person!$L$2:$L$1007,"DISCARDED") -> 64 | I5: =COUNTIF(Person!$L$2:$L$1007,"NEEDS DISCUSSION") -> 6 | J5: =COUNTIF('Review Needed'!$B$2:$B$997,A5) -> 44 | K5: Review business exceptions and legacy/file-layout rules isolated on Reviewed.
A6: Employment | B6: =COUNTA(Employment!$C$2:$C$1005) -> 184 | C6: =COUNTIF(Employment!$G$2:$G$1005,"STRUCTURAL") -> 125 | D6: =COUNTIF(Employment!$G$2:$G$1005,"BUSINESS") -> 59 | E6: =COUNTIF(Employment!$L$2:$L$1005,"SQL READY") -> 55 | F6: =COUNTIF(Employment!$L$2:$L$1005,"CUSTOM LOGIC") -> 0 | G6: =COUNTIF(Employment!$L$2:$L$1005,"HANDLED IN JSON VALIDATION") -> 63 | H6: =COUNTIF(Employment!$L$2:$L$1005,"DISCARDED") -> 19 | I6: =COUNTIF(Employment!$L$2:$L$1005,"NEEDS DISCUSSION") -> 47 | J6: =COUNTIF('Review Needed'!$B$2:$B$997,A6) -> 10 | K6: Review reference-data, cross-domain, historical, and downstream-state dependencies.
A7: Relationship | B7: =COUNTA(Relationship!$C$2:$C$1000) -> 126 | C7: =COUNTIF(Relationship!$G$2:$G$1000,"STRUCTURAL") -> 123 | D7: =COUNTIF(Relationship!$G$2:$G$1000,"BUSINESS") -> 3 | E7: =COUNTIF(Relationship!$K$2:$K$1000,"SQL READY") -> 0 | I7: =COUNTIF(Relationship!$K$2:$K$1000,"NEEDS DISCUSSION") -> 0 | J7: =COUNTIF('Review Needed'!$B$2:$B$997,A7) -> 61 | K7: Review parent-person, contact consistency, and legacy employee-demographic rules.
A8: Total | B8: =SUM(B5:B7) -> 503 | C8: =SUM(C5:C7) -> 435 | D8: =SUM(D5:D7) -> 68 | E8: =SUM(E5:E7) -> 110 | I8: =SUM(I5:I7) -> 53 | J8: =SUM(J5:J7) -> 115
A11: Review guidance
A12: Item | B12: Meaning / requested action
A13: SQL READY | B13: Spark-native boolean expression that returns TRUE when the record satisfies the rule and can be passed to pyspark.sql.functions.expr().
A14: NEEDS DISCUSSION | B14: A complete predicate cannot be finalized without an approved reference list, external dataset, business key, historical policy, or outcome decision.
A15: Reviewed tab | B15: Source rules whose target is absent from the approved domain JSON schema, is mixed with non-schema targets, or is not identified.
A16: Source precedence | B16: Approved Person, Employment, Relationship, and common-definition JSON contracts take precedence for field path, datatype, nullability, format, and structural constraint.
A17: Review date | B17: Prepared for product review as of 2026-07-29.

Sheet Person
A1: Source System | B1: Domain | C1: Validation ID | D1: Error Code | E1: Column Name | F1: Rule Scope | G1: Rule Category | H1: Rule Type | I1: Validation Rule | J1: Spark SQL Expression | K1: Spark SQL Expressions recommendations | L1: SQL Status | M1: Review | N1: Discussion Reason | O1: Data Type | P1: Length/Range | Q1: Allowed Values | R1: Severity | S1: Implementation Status | T1: Product Error Code | U1: Product Validation ID | V1: Product Error Code2 | W1: Duplicates
A2: SmartDEV | B2: Person | C2: VAL-00012 | D2: ERR-PER-00012 | E2: employerCode | F2: FIELD | G2: STRUCTURAL | H2: REQUIRED | I2: employerCode is required and must not be NULL or blank. Must be between 1 and 4 bytes. | J2: `employerCode` IS NOT NULL AND trim(`employerCode`) <> '' | K2: `employerCode` IS NOT NULL AND trim(cast(`employerCode` as string)) <> '' /* schema:required, valid:field_match, datafiles:match, db:column_match */ | baseline: `employerCode` IS NOT NULL AND trim(`employerCode`) <> '' | L2: HANDLED IN JSON VALIDATION | M2: VALIDATED | O2: string | P2: 1-4 characters | S2: Legacy/current implemented
A3: SmartDEV | B3: Person | C3: VAL-00013 | D3: ERR-PER-00013 | E3: lastName | F3: FIELD | G3: STRUCTURAL | H3: REQUIRED | I3: lastName is required and must not be blank. Must be between 1 and 100 bytes. DUPLICATE SEE ROW 30. | J3: `lastName` IS NOT NULL AND trim(`lastName`) <> '' | K3: `lastName` IS NOT NULL AND trim(cast(`lastName` as string)) <> '' /* schema:required, valid:no_match, datafiles:match, db:column_match */ | baseline: `lastName` IS NOT NULL AND trim(`lastName`) <> '' | L3: HANDLED IN JSON VALIDATION | M3: VALIDATED | N3: The json schema validates length of characters instead of bytes | O3: string | P3: 1-100 characters | S3: Legacy/current implemented
A4: SmartDEV | B4: Person | C4: VAL-00014 | D4: ERR-PER-00014 | E4: firstName | F4: FIELD | G4: STRUCTURAL | H4: REQUIRED | I4: firstName is required and must not be blank. Must be between 1 and 60 bytes. DUPLICATE SEE ROW 29. | J4: `firstName` IS NOT NULL AND trim(`firstName`) <> '' | K4: `firstName` IS NOT NULL AND trim(cast(`firstName` as string)) <> '' /* schema:required, valid:no_match, datafiles:match, db:column_match */ | baseline: `firstName` IS NOT NULL AND trim(`firstName`) <> '' | L4: HANDLED IN JSON VALIDATION | M4: VALIDATED | N4: The json schema validates length of characters instead of bytes | O4: string | P4: 1-60 characters | S4: Legacy/current implemented
A5: SmartDEV | B5: Person | C5: VAL-00015 | D5: ERR-PER-00015 | E5: dateOfBirth | F5: FIELD | G5: STRUCTURAL | H5: REQUIRED | I5: dateOfBirth is required and must not be blank. i.e. 1990-01-03 00:00:00 | J5: `dateOfBirth` IS NOT NULL AND trim(`dateOfBirth`) <> '' | K5: `dateOfBirth` IS NOT NULL AND trim(cast(`dateOfBirth` as string)) <> '' /* schema:required, valid:field_match, datafiles:match, db:column_match */ | baseline: `dateOfBirth` IS NOT NULL AND trim(`dateOfBirth`) <> '' | L5: HANDLED IN JSON VALIDATION | M5: VALIDATED | O5: string (date) | S5: Legacy/current implemented
A6: SmartDEV | B6: Person | C6: VAL-00016 | D6: ERR-PER-00016 | E6: personType | F6: FIELD | G6: STRUCTURAL | H6: REQUIRED | I6: personType is required and must not be NULL or blank. | J6: `personType` IS NOT NULL AND trim(`personType`) <> '' | K6: `personType` IS NOT NULL AND trim(cast(`personType` as string)) <> '' /* schema:required, valid:no_match, datafiles:match, db:column_match */ | baseline: `personType` IS NOT NULL AND trim(`personType`) <> '' | L6: HANDLED IN JSON VALIDATION | M6: VALIDATED | O6: string | Q6: EMPLOYEE | S6: Legacy/current implemented
A7: SmartDEV | B7: Person | C7: VAL-00017 | D7: ERR-PER-00017 | E7: taxIdNumber | F7: FIELD | G7: STRUCTURAL | H7: REQUIRED | I7: taxIdNumber is required and must not be NULL or blank. SQL This validates format and rejects all zeros; it does not verify that the IRS issued the number. | J7: "taxIdNumber" IS NOT NULL AND trim("taxIdNumber") <> '' AND trim("taxIdNumber") ~ '^\d{2}-?\d{7}$' AND regexp_replace(trim("taxIdNumber"), '\D', '', 'g') <> '000000000' | K7: `taxIdNumber` IS NOT NULL AND trim(cast(`taxIdNumber` as string)) <> '' /* schema:optional, valid:field_match, datafiles:match, db:column_match */ | baseline: "taxIdNumber" IS NOT NULL AND trim("taxIdNumber") <> '' AND trim("taxIdNumber") ~ '^\d{2}-?\d{7}$' AND regexp_replace(trim("taxIdNumber"), '\D', '', 'g') <> '000000000' | L7: DISCARDED | N7: Field is nullable as per json schema | O7: string | P7: 9-256 characters | S7: Legacy/current implemented
A8: SmartDEV | B8: Person | C8: VAL-00018 | D8: ERR-PER-00018 | E8: taxIdType | F8: FIELD | G8: STRUCTURAL | H8: REQUIRED | I8: taxIdType is required and must not be blank. | J8: "taxIdType" IS NOT NULL AND trim("taxIdType") <> '' AND upper(trim("taxIdType")) IN ('SSN', 'ITIN') | K8: `taxIdType` IS NOT NULL AND trim(cast(`taxIdType` as string)) <> '' /* schema:optional, valid:no_match, datafiles:match, db:check_mapping */ | baseline: "taxIdType" IS NOT NULL AND trim("taxIdType") <> '' AND upper(trim("taxIdType")) IN ('SSN', 'ITIN') | L8: DISCARDED | N8: Field is nullable as per json schema | O8: string | Q8: SSN, ITIN | S8: Legacy/current implemented
A9: SmartDEV | B9: Person | C9: VAL-00019 | D9: ERR-PER-00019 | E9: primaryAddressType | F9: FIELD | G9: STRUCTURAL | H9: REQUIRED | I9: primaryAddressType is required and must not be blank. | J9: primaryAddressType" IS NOT NULL AND trim("primaryAddressType") <> '' | K9: `primaryAddressType` IS NOT NULL AND trim(cast(`primaryAddressType` as string)) <> '' /* schema:optional, valid:no_match, datafiles:match, db:column_match */ | baseline: primaryAddressType" IS NOT NULL AND trim("primaryAddressType") <> '' | L9: DISCARDED | N9: Field not present required list of json schema | O9: string | Q9: H, W, A | S9: Legacy/current implemented
A10: SmartDEV | B10: Person | C10: VAL-00020 | D10: ERR-PER-00020 | E10: addresses | F10: FIELD | G10: STRUCTURAL | H10: REQUIRED | I10: There is no addresses field in person_schema.json. | K10: `addresses` IS NOT NULL AND trim(cast(`addresses` as string)) <> '' /* schema:optional, valid:no_match, datafiles:check, db:column_match */ | L10: DISCARDED | N10: addresses can be null | O10: array | S10: Legacy/current implemented
A11: SmartDEV | B11: Person | C11: VAL-00021 | D11: ERR-PER-00021 | E11: addresses[].streetAddress | F11: FIELD | G11: STRUCTURAL | H11: REQUIRED | I11: addresses[].streetAddress is required and must not be blank. | J11: `addresses` IS NOT NULL AND size(`addresses`) > 0 AND forall( `addresses`, address_item -> address_item.`streetAddress` IS NULL OR trim(address_item.`streetAddress`) = '' OR octet_length(trim(address_item.`streetAddress`)) < 200 ) | K11: `addresses[].streetAddress` IS NOT NULL AND trim(cast(`addresses[].streetAddress` as string)) <> '' /* schema:unmapped, valid:no_match, datafiles:match, db:column_match */ | baseline: `addresses` IS NOT NULL AND size(`addresses`) > 0 AND forall( `addresses`, address_item -> address_item.`streetAddress` IS NULL OR trim(address_item.`streetAddress`) = | L11: DISCARDED | N11: Field is nullable as per json schema | O11: string | P11: ≤ 200 characters | S11: Legacy/current implemented
A12: SmartDEV | B12: Person | C12: VAL-00022 | D12: ERR-PER-00022 | E12: addresses[].city | F12: FIELD | G12: STRUCTURAL | H12: REQUIRED | I12: addresses[].city is required and must not be blank. We should create a city reference table to validate against? If we use a reference table we do not need structural validation. | J12: `addresses` IS NOT NULL AND size(`addresses`) > 0 AND forall( `addresses`, address_item -> address_item.`city` IS NOT NULL AND trim(address_item.`city`) <> '' AND octet_length(trim(address_item.`city`)) <= 50 AND upper(trim(address_item.`city`)) IN ( SELECT upper(trim(`city`)) FROM `city_reference` WHERE `city` IS NOT NULL ) ) | K12: `addresses[].city` IS NOT NULL AND trim(cast(`addresses[].city` as string)) <> '' /* schema:unmapped, valid:no_match, datafiles:match, db:column_match */ | baseline: `addresses` IS NOT NULL AND size(`addresses`) > 0 AND forall( `addresses`, address_item -> address_item.`city` IS NOT NULL AND trim(address_item.`city`) <> '' AND o | L12: DISCARDED | N12: Field can be nullable | O12: string | P12: ≤ 50 characters | S12: Legacy/current implemented
A13: SmartDEV | B13: Person | C13: VAL-00023 | D13: ERR-PER-00023 | E13: addresses[].state | F13: FIELD | G13: STRUCTURAL | H13: REQUIRED | I13: addresses[].state is required and must not be blank. We should create a state reference table to validate against? If we use a reference table we do not need structural validation. | J13: `addresses` IS NOT NULL AND size(`addresses`) > 0 AND forall( `addresses`, address_item -> address_item.`state` IS NOT NULL AND trim(address_item.`state`) <> '' AND upper(trim(address_item.`state`)) IN ( SELECT upper(trim(`state_code`)) FROM `state_reference` WHERE `state_code` IS NOT NULL ) ) | K13: `addresses[].state` IS NOT NULL AND trim(cast(`addresses[].state` as string)) <> '' /* schema:unmapped, valid:no_match, datafiles:match, db:column_match */ | baseline: `addresses` IS NOT NULL AND size(`addresses`) > 0 AND forall( `addresses`, address_item -> address_item.`state` IS NOT NULL AND trim(address_item.`state`) <> '' AND | L13: DISCARDED | N13: Field can be nullable | O13: string | P13: ≤ 4 characters | S13: Legacy/current implemented
A14: SmartDEV | B14: Person | C14: VAL-00024 | D14: ERR-PER-00024 | E14: addresses[].zipCode | F14: FIELD | G14: STRUCTURAL | H14: REQUIRED | I14: addresses[].zipCode is required and must not be NULL or blank. We should create a zip reference table to validate against? If we use a reference table we do not need structural validation. | J14: `addresses` IS NOT NULL AND size(`addresses`) > 0 AND forall( `addresses`, address_item -> address_item.`zipCode` IS NOT NULL AND trim(address_item.`zipCode`) <> '' AND trim(address_item.`zipCode`) IN ( SELECT trim(`zip_code`) FROM `zip_reference` WHERE `zip_code` IS NOT NULL ) ) | K14: `addresses[].zipCode` IS NOT NULL AND trim(cast(`addresses[].zipCode` as string)) <> '' /* schema:unmapped, valid:no_match, datafiles:match, db:column_match */ | baseline: `addresses` IS NOT NULL AND size(`addresses`) > 0 AND forall( `addresses`, address_item -> address_item.`zipCode` IS NOT NULL AND trim(address_item.`zipCode`) <> '' | L14: DISCARDED | N14: Field can be nullable | O14: string | P14: ≤ 10 characters | S14: Legacy/current implemented
A15: SmartDEV | B15: Person | C15: VAL-00025 | D15: ERR-PER-00025 | E15: addresses[].country | F15: FIELD | G15: STRUCTURAL | H15: REQUIRED | I15: addresses[].country is required and must not be NULL or blank. We should create a country reference table to validate against? If we use a reference table we do not need structural validation. | J15: `addresses` IS NOT NULL AND size(`addresses`) > 0 AND forall( `addresses`, address_item -> address_item.`country` IS NOT NULL AND trim(address_item.`country`) <> '' AND upper(trim(address_item.`country`)) IN ( SELECT upper(trim(`country_code`)) FROM `country_reference` WHERE `country_code` IS NOT NULL ) ) | K15: `addresses[].country` IS NOT NULL AND trim(cast(`addresses[].country` as string)) <> '' /* schema:unmapped, valid:no_match, datafiles:match, db:column_match */ | baseline: `addresses` IS NOT NULL AND size(`addresses`) > 0 AND forall( `addresses`, address_item -> address_item.`country` IS NOT NULL AND trim(address_item.`country`) <> '' | L15: DISCARDED | N15: Field can be null as per Json schema | O15: string | P15: ≤ 2 characters | S15: Legacy/current implemented
A16: SmartDEV | B16: Person | C16: VAL-00026 | D16: ERR-PER-00026 | E16: emails[].emailType | F16: FIELD | G16: STRUCTURAL | H16: REQUIRED | I16: emails[].emailType is required and must not be blank. Value must be W, P or A. | J16: `emails` IS NULL OR forall( `emails`, email_item -> email_item.`emailType` IS NOT NULL AND trim(email_item.`emailType`) <> '' AND upper(trim(email_item.`emailType`)) IN ('W', 'P', 'A') ) | K16: `emails[].emailType` IS NOT NULL AND trim(cast(`emails[].emailType` as string)) <> '' /* schema:unmapped, valid:no_match, datafiles:match, db:column_match */ | baseline: `emails` IS NULL OR forall( `emails`, email_item -> email_item.`emailType` IS NOT NULL AND trim(email_item.`emailType`) <> '' AND upper(trim(email_item.`emailType`) | L16: DISCARDED | N16: Field can be null | O16: string | Q16: W, P, A | S16: Legacy/current implemented
A17: SmartDEV | B17: Person | C17: VAL-00027 | D17: ERR-PER-00027 | E17: emails[].email | F17: FIELD | G17: STRUCTURAL | H17: REQUIRED | I17: emails[].email is required and must not be blank. | J17: `emails` IS NULL OR forall( `emails`, email_item -> email_item.`emailAddress` IS NOT NULL AND trim(email_item.`emailAddress`) <> '' AND trim(email_item.`emailAddress`) RLIKE '^[A-Za-z0-9.!#$%&''*+/=?^_`{|}~-]+@[A-Za-z0-9-]+(\\.[A-Za-z0-9-]+)+$' ) | K17: `emails[].email` IS NOT NULL AND trim(cast(`emails[].email` as string)) <> '' /* schema:unmapped, valid:no_match, datafiles:match, db:check_mapping */ | baseline: `emails` IS NULL OR forall( `emails`, email_item -> email_item.`emailAddress` IS NOT NULL AND trim(email_item.`emailAddress`) <> '' AND trim(email_item.`emailAddres | L17: DISCARDED | N17: field can be nullable | O17: string | P17: ≤ 254 characters | S17: Legacy/current implemented
A18: SmartDEV | B18: Person | C18: VAL-00028 | D18: ERR-PER-00028 | E18: phones[].phoneNumber | F18: FIELD | G18: STRUCTURAL | H18: REQUIRED | I18: phones[].phoneNumber is required and must not be NULL or blank. | J18: `phones` IS NULL OR forall( `phones`, phone_item -> phone_item.`phoneNumber` IS NOT NULL AND trim(phone_item.`phoneNumber`) <> '' AND regexp_replace( trim(phone_item.`phoneNumber`), '[^0-9]', '' ) RLIKE '^1?[2-9][0-9]{2}[2-9][0-9]{6}$' ) | K18: `phones[].phoneNumber` IS NOT NULL AND trim(cast(`phones[].phoneNumber` as string)) <> '' /* schema:unmapped, valid:no_match, datafiles:match, db:column_match */ | baseline: `phones` IS NULL OR forall( `phones`, phone_item -> phone_item.`phoneNumber` IS NOT NULL AND trim(phone_item.`phoneNumber`) <> '' AND regexp_replace( trim | L18: DISCARDED | N18: Phone number can be null as per Json Schema. The regex pattern only validates the american phone numbers. This check is not present in Json schema | O18: string | P18: ≤ 15 characters | S18: Legacy/current implemented
A19: SmartDEV | B19: Person | C19: VAL-00957 | D19: ERR-PER-00957 | E19: employerCode | F19: FIELD | G19: STRUCTURAL | H19: DATA_TYPE | I19: employerCode must have datatype string. | J19: typeof(`employerCode`) = 'string' | K19: `employerCode` IS NULL OR typeof(`employerCode`) = 'string' /* schema:required, valid:field_match, datafiles:match, db:column_match */ | baseline: typeof(`employerCode`) = 'string' | L19: HANDLED IN JSON VALIDATION | M19: VALIDATED | O19: string | P19: 1-4 characters | S19: Legacy/current implemented
A20: SmartDEV | B20: Person | C20: VAL-00958 | D20: ERR-PER-00958 | E20: employerCode | F20: FIELD | G20: STRUCTURAL | H20: MAX_LENGTH | I20: employerCode must not exceed 4 characters. | J20: see above | K20: `employerCode` IS NULL OR length(cast(`employerCode` as string)) <= 1 /* schema:required, valid:field_match, datafiles:match, db:column_match */ | baseline: see above | L20: DISCARDED | N20: Not required as we are validating the pattern | O20: string | P20: 1-4 characters | S20: Legacy/current implemented
A21: SmartDEV | B21: Person | C21: VAL-00959 | D21: ERR-PER-00959 | E21: employerCode | F21: FIELD | G21: STRUCTURAL | H21: PATTERN | I21: Value must match the business-approved pattern | J21: `employerCode` RLIKE '^[A-Za-z0-9]{1,4}$' | K21: `employerCode` RLIKE '^[A-Za-z0-9]{1,4}$' /* schema:required, valid:field_match, datafiles:match, db:column_match */ | L21: SQL READY | M21: VALIDATED | O21: string | P21: 1-4 characters | Q21: E001 | S21: Potential candidate from Data Files Excel
A22: SmartDEV | B22: Person | C22: VAL-00960 | D22: ERR-PER-00960 | E22: sourceFileName | F22: FIELD | G22: STRUCTURAL | H22: REQUIRED | I22: sourceFileName is required and must not be blank. | J22: `sourceFileName` IS NOT NULL AND trim(`sourceFileName`) <> '' AND length(trim(`sourceFileName`)) <= 255 AND upper(trim(`sourceFileName`)) RLIKE '^[0-9]{2}PERSONAL[0-9]{8}$' | K22: `sourceFileName` IS NOT NULL AND trim(cast(`sourceFileName` as string)) <> '' /* schema:optional, valid:no_match, datafiles:match, db:column_match */ | baseline: `sourceFileName` IS NOT NULL AND trim(`sourceFileName`) <> '' AND length(trim(`sourceFileName`)) <= 255 AND upper(trim(`sourceFileName`)) RLIKE '^[0-9]{2}PERSONAL[0-9]{8}$' | L22: DISCARDED | N22: Field is nullable in schema json | O22: string | P22: ≤ 255 characters | Q22: 01_PERSONAL_MMDDYYYY | S22: Potential candidate from Data Files Excel
A23: SmartDEV | B23: Person | C23: VAL-00961 | D23: ERR-PER-00961 | E23: sourceFileName | F23: FIELD | G23: STRUCTURAL | H23: DATA_TYPE | I23: Validate numeric/decimal format; reject non-numeric characters except allowed decimal/sign characters. | J23: `sourceFileName` IS NULL OR (typeof(`sourceFileName`) = 'string') | K23: `sourceFileName` IS NULL OR cast(`sourceFileName` as decimal(38,10)) IS NOT NULL /* schema:optional, valid:no_match, datafiles:match, db:column_match */ | baseline: `sourceFileName` IS NULL OR (typeof(`sourceFileName`) = 'string') | L23: HANDLED IN JSON VALIDATION | M23: VALIDATED | O23: string | P23: ≤ 255 characters | Q23: 01_PERSONAL_MMDDYYYY | S23: Potential candidate from Data Files Excel
A24: SmartDEV | B24: Person | C24: VAL-00962 | D24: ERR-PER-00962 | E24: sourceFileName | F24: FIELD | G24: STRUCTURAL | H24: MAX_LENGTH | I24: sourceFileName must not exceed 255 characters. | J24: `sourceFileName` IS NULL OR (length(`sourceFileName`) <= 255) | K24: `sourceFileName` IS NULL OR length(cast(`sourceFileName` as string)) <= 255 /* schema:optional, valid:no_match, datafiles:match, db:column_match */ | baseline: `sourceFileName` IS NULL OR (length(`sourceFileName`) <= 255) | L24: SQL READY | M24: VALIDATED | O24: string | P24: ≤ 255 characters | Q24: 01_PERSONAL_MMDDYYYY | S24: Potential candidate from Data Files Excel
A25: SmartDEV | B25: Person | C25: VAL-00963 | D25: ERR-PER-00963 | E25: sourceFileName | F25: FIELD | G25: STRUCTURAL | H25: ALLOWED_VALUES | I25: Value must match workbook example code list or Reference Table where defined; codes should be compared after trim and case normalization only where business-approved. | J25: see above | K25: `sourceFileName` IS NULL OR upper(trim(cast(`sourceFileName` as string))) IN ('01_PERSONAL_MMDDYYYY') /* schema:optional, valid:no_match, datafiles:match, db:column_match */ | baseline: see above | L25: DISCARDED | N25: Approved allowed values are not supplied in the JSON schema or in a definitive product rule. | O25: string | P25: ≤ 255 characters | Q25: 01_PERSONAL_MMDDYYYY | S25: Potential candidate from Data Files Excel
A26: SmartDEV | B26: Person | C26: VAL-00968 | D26: ERR-PER-00968 | E26: uniqueId | F26: FIELD | G26: STRUCTURAL | H26: REQUIRED | I26: uniqueId is required and must not be NULL or blank. | J26: `uniqueId` IS NOT NULL AND trim(`uniqueId`) <> '' | K26: `uniqueId` IS NOT NULL AND trim(cast(`uniqueId` as string)) <> '' /* schema:required, valid:no_match, datafiles:check, db:column_match */ | baseline: `uniqueId` IS NOT NULL AND trim(`uniqueId`) <> '' | L26: HANDLED IN JSON VALIDATION | M26: VALIDATED | O26: string | P26: 1-64 characters | Q26: TBD | S26: Potential candidate from Data Files Excel
A27: SmartDEV | B27: Person | C27: VAL-00969 | D27: ERR-PER-00969 | E27: uniqueId | F27: FIELD | G27: STRUCTURAL | H27: DATA_TYPE | I27: Validate numeric/decimal format; reject non-numeric characters except allowed decimal/sign characters. | J27: typeof(`uniqueId`) = 'string' | K27: `uniqueId` IS NULL OR cast(`uniqueId` as decimal(38,10)) IS NOT NULL /* schema:required, valid:no_match, datafiles:check, db:column_match */ | baseline: typeof(`uniqueId`) = 'string' | L27: HANDLED IN JSON VALIDATION | M27: VALIDATED | O27: string | P27: 1-64 characters | Q27: TBD | S27: Potential candidate from Data Files Excel
A28: SmartDEV | B28: Person | C28: VAL-00970 | D28: ERR-PER-00970 | E28: uniqueId | F28: FIELD | G28: STRUCTURAL | H28: MAX_LENGTH | I28: uniqueId must not exceed 64 characters. | J28: length(`uniqueId`) <= 64 | K28: `uniqueId` IS NULL OR length(cast(`uniqueId` as string)) <= 1 /* schema:required, valid:no_match, datafiles:check, db:column_match */ | baseline: length(`uniqueId`) <= 64 | L28: SQL READY | M28: VALIDATED | O28: string | P28: 1-64 characters | Q28: TBD | S28: Potential candidate from Data Files Excel
A29: SmartDEV | B29: Person | C29: VAL-01006 | D29: ERR-PER-01006 | E29: uniqueId | F29: FIELD | G29: STRUCTURAL | H29: PATTERN | I29: uniqueId must contain only letters, numbers, period (.), underscore (_), colon (:), or hyphen (-), and be 1 to 64 characters long. | J29: `uniqueId` RLIKE '^[A-Za-z0-9._:-]{1,64}$' | K29: `uniqueId` RLIKE '^[A-Za-z0-9._:-]{1,64}$' /* schema:required, valid:no_match, datafiles:check, db:column_match */ | L29: SQL READY | M29: VALIDATED | O29: string | P29: 1-64 characters | Q29: TBD | S29: Potential candidate from Data Files Excel
A30: SmartDEV | B30: Person | C30: VAL-00991 | D30: ERR-PER-00991 | E30: firstName | F30: FIELD | G30: STRUCTURAL | H30: DATA_TYPE | I30: firstName must have datatype string. | J30: `firstName` IS NULL OR (typeof(`firstName`) = 'string') | K30: `firstName` IS NULL OR typeof(`firstName`) = 'string' /* schema:required, valid:no_match, datafiles:match, db:column_match */ | baseline: `firstName` IS NULL OR (typeof(`firstName`) = 'string') | L30: HANDLED IN JSON VALIDATION | M30: VALIDATED | O30: string | P30: 1-60 characters | S30: Legacy/current implemented
A31: SmartDEV | B31: Person | C31: VAL-00992 | D31: ERR-PER-00992 | E31: firstName | F31: FIELD | G31: STRUCTURAL | H31: MAX_LENGTH | I31: firstName must not exceed 60 characters. | J31: `firstName` IS NULL OR (length(`firstName`) <= 60) | K31: `firstName` IS NULL OR length(cast(`firstName` as string)) <= 1 /* schema:required, valid:no_match, datafiles:match, db:column_match */ | baseline: `firstName` IS NULL OR (length(`firstName`) <= 60) | L31: SQL READY | M31: VALIDATED | O31: string | P31: 1-60 characters | S31: Legacy/current implemented
A32: SmartDEV | B32: Person | C32: VAL-00993 | D32: ERR-PER-00993 | E32: middleName | F32: FIELD | G32: STRUCTURAL | H32: DATA_TYPE | I32: Validate field according to workbook data type 'nameFlexible'. | J32: `middleName` IS NULL OR (typeof(`middleName`) = 'string') | K32: `middleName` IS NULL OR typeof(`middleName`) = 'string' /* schema:optional, valid:no_match, datafiles:match, db:column_match */ | baseline: `middleName` IS NULL OR (typeof(`middleName`) = 'string') | L32: HANDLED IN JSON VALIDATION | M32: VALIDATED | O32: string | P32: ≤ 100 characters | Q32: J. | S32: Potential candidate from Data Files Excel
A33: SmartDEV | B33: Person | C33: VAL-00994 | D33: ERR-PER-00994 | E33: middleName | F33: FIELD | G33: STRUCTURAL | H33: MAX_LENGTH | I33: middleName must not exceed 100 characters. | J33: `middleName` IS NULL OR (length(`middleName`) <= 100) | K33: `middleName` IS NULL OR length(cast(`middleName` as string)) <= 100 /* schema:optional, valid:no_match, datafiles:match, db:column_match */ | baseline: `middleName` IS NULL OR (length(`middleName`) <= 100) | L33: SQL READY | M33: VALIDATED | O33: string | P33: ≤ 100 characters | Q33: J. | S33: Potential candidate from Data Files Excel
A34: SmartDEV | B34: Person | C34: VAL-00996 | D34: ERR-PER-00996 | E34: lastName | F34: FIELD | G34: STRUCTURAL | H34: DATA_TYPE | I34: lastName must have datatype string. | J34: typeof(`lastName`) = 'string' | K34: `lastName` IS NULL OR typeof(`lastName`) = 'string' /* schema:required, valid:no_match, datafiles:match, db:column_match */ | baseline: typeof(`lastName`) = 'string' | L34: HANDLED IN JSON VALIDATION | M34: VALIDATED | O34: string | P34: 1-100 characters | S34: Legacy/current implemented
A35: SmartDEV | B35: Person | C35: VAL-00997 | D35: ERR-PER-00997 | E35: lastName | F35: FIELD | G35: STRUCTURAL | H35: MAX_LENGTH | I35: lastName must not exceed 100 characters. | J35: length(`lastName`) <= 100 | K35: `lastName` IS NULL OR length(cast(`lastName` as string)) <= 1 /* schema:required, valid:no_match, datafiles:match, db:column_match */ | baseline: length(`lastName`) <= 100 | L35: SQL READY | M35: VALIDATED | O35: string | P35: 1-100 characters | S35: Legacy/current implemented
A36: SmartDEV | B36: Person | C36: VAL-00999 | D36: ERR-PER-00999 | E36: taxIdNumber | F36: FIELD | G36: STRUCTURAL | H36: DATA_TYPE | I36: taxIdNumber must have datatype string. | J36: `taxIdNumber` IS NULL OR ( typeof(`taxIdNumber`) = 'string' ) | K36: `taxIdNumber` IS NULL OR cast(`taxIdNumber` as decimal(38,10)) IS NOT NULL /* schema:optional, valid:field_match, datafiles:match, db:column_match */ | baseline: `taxIdNumber` IS NULL OR ( typeof(`taxIdNumber`) = 'string' ) | L36: HANDLED IN JSON VALIDATION | M36: VALIDATED | O36: string | P36: 9-256 characters | S36: Legacy/current implemented
A37: SmartDEV | B37: Person | C37: VAL-01000 | D37: ERR-PER-01000 | E37: taxIdNumber | F37: FIELD | G37: STRUCTURAL | H37: PATTERN | I37: taxIdNumber must be null, a 9-digit raw Tax ID, or an encrypted/HMAC value of 32 to 256 permitted characters. | J37: `taxIdNumber` IS NULL OR `taxIdNumber` RLIKE '^[0-9]{9}$' OR `taxIdNumber` RLIKE '^[A-Za-z0-9+/=_:-]{32,256}$' | K37: `taxIdNumber` IS NULL OR `taxIdNumber` RLIKE '^[0-9]{9}$' OR `taxIdNumber` RLIKE '^[A-Za-z0-9+/=_:-]{32,256}$' /* schema:optional, valid:field_match, datafiles:match, db:column_match */ | L37: SQL READY | M37: VALIDATED | O37: string | P37: 9-256 characters | S37: Legacy/current implemented
A38: SmartDEV | B38: Person | C38: VAL-01001 | D38: ERR-PER-01001 | E38: taxIdNumber | F38: FIELD | G38: STRUCTURAL | H38: ALLOWED_VALUES | I38: Value must match workbook example code list or Reference Table where defined; codes should be compared after trim and case normalization only where business-approved. | J38: see above | K38: `taxIdNumber` IS NULL OR upper(trim(cast(`taxIdNumber` as string))) IN ('XXX-XX-1234') /* schema:optional, valid:field_match, datafiles:match, db:column_match */ | baseline: see above | L38: DISCARDED | N38: No reference lookup required | O38: string | P38: 9-256 characters | Q38: XXX-XX-1234 | S38: Potential candidate from Data Files Excel
A39: SmartDEV | B39: Person | C39: VAL-01002 | D39: ERR-PER-01002 | E39: taxIdType | F39: FIELD | G39: STRUCTURAL | H39: DATA_TYPE | I39: taxIdType must have datatype string. | J39: `taxIdType` IS NULL OR (typeof(`taxIdType`) = 'string') | K39: `taxIdType` IS NULL OR typeof(`taxIdType`) = 'string' /* schema:optional, valid:no_match, datafiles:match, db:check_mapping */ | baseline: `taxIdType` IS NULL OR (typeof(`taxIdType`) = 'string') | L39: HANDLED IN JSON VALIDATION | M39: VALIDATED | O39: string | Q39: SSN, ITIN | S39: Legacy/current implemented
A40: SmartDEV | B40: Person | C40: VAL-01003 | D40: ERR-PER-01003 | E40: taxIdType | F40: FIELD | G40: STRUCTURAL | H40: MAX_LENGTH | I40: Field length must be <= 4 characters/digits as defined in the workbook. | J40: see above | K40: `taxIdType` IS NULL OR length(cast(`taxIdType` as string)) <= 4 /* schema:optional, valid:no_match, datafiles:match, db:check_mapping */ | baseline: see above | L40: DISCARDED | N40: Validation not needed as it checks allowed values | O40: string | P40: 4 | Q40: SSN, ITIN | S40: Potential candidate from Data Files Excel
...

Sheet Employment
A1: Source System | B1: Domain | C1: Validation ID | D1: Error Code | E1: Column Name | F1: Rule Scope | G1: Rule Category | H1: Rule Type | I1: Validation Rule | J1: Spark SQL Expression | K1: Spark SQL Expressions recommendations | L1: SQL Status | M1: Review | N1: Discussion Reason | O1: Data Type | P1: Length/Range | Q1: Allowed Values | R1: Severity | S1: Implementation Status | T1: Notes | U1: Source Detail | V1: Source Evidence | W1: Product Validation ID | X1: Product Error Code
A2: SmartDEV | B2: Employment | C2: VAL-01296 | D2: ERR-EMP-01296 | E2: action | F2: FIELD | G2: STRUCTURAL | H2: DATA_TYPE | I2: action must match JSON Schema type string or null. | J2: `action` IS NULL OR (typeof(`action`) = 'string') | K2: `action` IS NULL OR typeof(`action`) = 'string' /* schema:optional, valid:no_match, datafiles:match, db:column_match */ | baseline: `action` IS NULL OR (typeof(`action`) = 'string') | L2: HANDLED IN JSON VALIDATION | M2: VALIDATED | O2: string | Q2: HIR, RHIR, LOA, RTW, XFER, TRM, HRS, CLS, LOC, PAY, RET, DTH, DIV, DIS, CONT | S2: Schema-aligned candidate | T2: Represents the HR action; Cross reference with "Emp Status Map"; Codes are coming on the data file; Schema-aligned structural validation; raw JSON Schema validation occurs before Spark parsing. | U2: Data Files Excel candidate; Approved Employment JSON contract | V2: Data Files07102026.xlsx::Employment!row 24; User-provided Employment JSON Schema/common definitions
A3: SmartDEV | B3: Employment | C3: VAL-01315 | D3: ERR-EMP-01315 | E3: businessUnitCode | F3: FIELD | G3: STRUCTURAL | H3: DATA_TYPE | I3: businessUnitCode must match JSON Schema type string or null. | J3: `businessUnitCode` IS NULL OR (typeof(`businessUnitCode`) = 'string') | K3: `businessUnitCode` IS NULL OR typeof(`businessUnitCode`) = 'string' /* schema:optional, valid:no_match, datafiles:check, db:column_match */ | baseline: `businessUnitCode` IS NULL OR (typeof(`businessUnitCode`) = 'string') | L3: HANDLED IN JSON VALIDATION | M3: VALIDATED | O3: string | P3: ≤ 8 characters | S3: Schema-aligned candidate | T3: Business unit; Schema-aligned structural validation; raw JSON Schema validation occurs before Spark parsing. | U3: Data Files Excel candidate; Approved Employment JSON contract | V3: Data Files07102026.xlsx::Employment!row 30 | Data Files07102026.xlsx::SmartDEV!row 46; User-provided Employment JSON Schema/common definitions
A4: SmartDEV | B4: Employment | C4: VAL-01316 | D4: ERR-EMP-01316 | E4: businessUnitCode | F4: FIELD | G4: STRUCTURAL | H4: MAX_LENGTH | I4: businessUnitCode must not exceed 8 characters. | J4: `businessUnitCode` IS NULL OR (length(`businessUnitCode`) <= 8) | K4: `businessUnitCode` IS NULL OR length(cast(`businessUnitCode` as string)) <= 8 /* schema:optional, valid:no_match, datafiles:check, db:column_match */ | baseline: `businessUnitCode` IS NULL OR (length(`businessUnitCode`) <= 8) | L4: SQL READY | M4: VALIDATED | O4: string | P4: ≤ 8 characters | S4: Schema-aligned candidate | T4: Business unit; Schema-aligned structural validation; raw JSON Schema validation occurs before Spark parsing. | U4: Data Files Excel candidate; Approved Employment JSON contract | V4: Data Files07102026.xlsx::Employment!row 30 | Data Files07102026.xlsx::SmartDEV!row 46; User-provided Employment JSON Schema/common definitions
A5: SmartDEV | B5: Employment | C5: VAL-02947 | D5: ERR-EMP-02947 | E5: clientId | F5: FIELD | G5: STRUCTURAL | H5: DATA_TYPE | I5: clientId must match JSON Schema type string or null. | J5: `clientId` IS NULL OR (typeof(`clientId`) = 'string') | K5: `clientId` IS NULL OR typeof(`clientId`) = 'string' /* schema:optional, valid:no_match, datafiles:check, db:column_match */ | baseline: `clientId` IS NULL OR (typeof(`clientId`) = 'string') | L5: HANDLED IN JSON VALIDATION | M5: VALIDATED | O5: string | P5: ≤ 64 characters | S5: Schema-aligned validation | T5: Structural validation is authoritative at the raw JSON stage before parsing payload fields into Spark. | U5: Approved Employment JSON contract | V5: User-provided Employment JSON Schema and common definitions
A6: SmartDEV | B6: Employment | C6: VAL-12947 | D6: ERR-EMP-12947 | E6: clientId | F6: FIELD | G6: STRUCTURAL | H6: PATTERN | I6: clientId must match JSON Schema pattern | J6: `clientId` IS NULL OR `clientId`RLIKE '^[A-Za-z0-9._:-]{1,64}$' | K6: `clientId` IS NULL OR typeof(`clientId`) = 'string' /* schema:optional, valid:no_match, datafiles:check, db:column_match */ | baseline: `clientId` IS NULL OR (typeof(`clientId`) = 'string') | L6: HANDLED IN JSON VALIDATION | M6: VALIDATED | O6: string | P6: ≤ 64 characters | S6: Schema-aligned validation | T6: Structural validation is authoritative at the raw JSON stage before parsing payload fields into Spark. | U6: Approved Employment JSON contract | V6: User-provided Employment JSON Schema and common definitions
A7: SmartDEV | B7: Employment | C7: VAL-01312 | D7: ERR-EMP-01312 | E7: departmentCode | F7: FIELD | G7: STRUCTURAL | H7: DATA_TYPE | I7: departmentCode must match JSON Schema type string or null. | J7: `departmentCode` IS NULL OR (typeof(`departmentCode`) = 'string') | K7: `departmentCode` IS NULL OR typeof(`departmentCode`) = 'string' /* schema:optional, valid:no_match, datafiles:check, db:column_match */ | baseline: `departmentCode` IS NULL OR (typeof(`departmentCode`) = 'string') | L7: HANDLED IN JSON VALIDATION | M7: VALIDATED | O7: string | P7: ≤ 8 characters | S7: Schema-aligned candidate | T7: Department/Division; Schema-aligned structural validation; raw JSON Schema validation occurs before Spark parsing. | U7: Data Files Excel candidate; Approved Employment JSON contract | V7: Data Files07102026.xlsx::Employment!row 29 | Data Files07102026.xlsx::SmartDEV!row 45; User-provided Employment JSON Schema/common definitions
A8: SmartDEV | B8: Employment | C8: VAL-01313 | D8: ERR-EMP-01313 | E8: departmentCode | F8: FIELD | G8: STRUCTURAL | H8: MAX_LENGTH | I8: departmentCode must not exceed 8 characters. | J8: `departmentCode` IS NULL OR (length(`departmentCode`) <= 8) | K8: `departmentCode` IS NULL OR length(cast(`departmentCode` as string)) <= 8 /* schema:optional, valid:no_match, datafiles:check, db:column_match */ | baseline: `departmentCode` IS NULL OR (length(`departmentCode`) <= 8) | L8: SQL READY | M8: VALIDATED | O8: string | P8: ≤ 8 characters | S8: Schema-aligned candidate | T8: Department/Division; Schema-aligned structural validation; raw JSON Schema validation occurs before Spark parsing. | U8: Data Files Excel candidate; Approved Employment JSON contract | V8: Data Files07102026.xlsx::Employment!row 29 | Data Files07102026.xlsx::SmartDEV!row 45; User-provided Employment JSON Schema/common definitions
A9: SmartDEV | B9: Employment | C9: VAL-01357 | D9: ERR-EMP-01357 | E9: dutyStationCityCode | F9: FIELD | G9: STRUCTURAL | H9: DATA_TYPE | I9: dutyStationCityCode must match JSON Schema type string or null. | J9: `dutyStationCityCode` IS NULL OR (typeof(`dutyStationCityCode`) = 'string') | K9: `dutyStationCityCode` IS NULL OR typeof(`dutyStationCityCode`) = 'string' /* schema:optional, valid:no_match, datafiles:match, db:check_mapping */ | baseline: `dutyStationCityCode` IS NULL OR (typeof(`dutyStationCityCode`) = 'string') | L9: HANDLED IN JSON VALIDATION | M9: VALIDATED | O9: string | P9: ≤ 8 characters | S9: Schema-aligned candidate | T9: 4-character OPM locality code parsed from positions 6-9 of the 9-character Duty Station composite, used for locality pay area determination and FEHB HMO geographic availability. 0000=not in city. Overseas: last 3 chars replaced with zeros by EHRI.; Schema-aligned structural validation; raw JSON Schema validation occurs before Spark parsing. | U9: Data Files Excel candidate; Approved Employment JSON contract | V9: Data Files07102026.xlsx::Employment!row 46; User-provided Employment JSON Schema/common definitions
A10: SmartDEV | B10: Employment | C10: VAL-01358 | D10: ERR-EMP-01358 | E10: dutyStationCityCode | F10: FIELD | G10: STRUCTURAL | H10: MAX_LENGTH | I10: dutyStationCityCode must not exceed 8 characters. | J10: `dutyStationCityCode` IS NULL OR (length(`dutyStationCityCode`) <= 8) | K10: `dutyStationCityCode` IS NULL OR length(cast(`dutyStationCityCode` as string)) <= 8 /* schema:optional, valid:no_match, datafiles:match, db:check_mapping */ | baseline: `dutyStationCityCode` IS NULL OR (length(`dutyStationCityCode`) <= 8) | L10: SQL READY | M10: VALIDATED | O10: string | P10: ≤ 8 characters | S10: Schema-aligned candidate | T10: 4-character OPM locality code parsed from positions 6-9 of the 9-character Duty Station composite, used for locality pay area determination and FEHB HMO geographic availability. 0000=not in city. Overseas: last 3 chars replaced with zeros by EHRI.; Schema-aligned structural validation; raw JSON Schema validation occurs before Spark parsing. | U10: Data Files Excel candidate; Approved Employment JSON contract | V10: Data Files07102026.xlsx::Employment!row 46; User-provided Employment JSON Schema/common definitions
A11: SmartDEV | B11: Employment | C11: VAL-01354 | D11: ERR-EMP-01354 | E11: dutyStationCountyCode | F11: FIELD | G11: STRUCTURAL | H11: DATA_TYPE | I11: dutyStationCountyCode must match JSON Schema type string or null. | J11: `dutyStationCountyCode` IS NULL OR (typeof(`dutyStationCountyCode`) = 'string') | K11: `dutyStationCountyCode` IS NULL OR typeof(`dutyStationCountyCode`) = 'string' /* schema:optional, valid:no_match, datafiles:match, db:column_match */ | baseline: `dutyStationCountyCode` IS NULL OR (typeof(`dutyStationCountyCode`) = 'string') | L11: HANDLED IN JSON VALIDATION | M11: VALIDATED | O11: string | P11: ≤ 8 characters | S11: Schema-aligned candidate | T11: 3-character FIPS county code parsed from positions 3-5 of the 9-character OPM Duty Station composite code. 000=not in county. VA: 013=Arlington. 059=Fairfax. MD: 031=Montgomery.; Schema-aligned structural validation; raw JSON Schema validation occurs before Spark parsing. | U11: Data Files Excel candidate; Approved Employment JSON contract | V11: Data Files07102026.xlsx::Employment!row 45; User-provided Employment JSON Schema/common definitions
A12: SmartDEV | B12: Employment | C12: VAL-01355 | D12: ERR-EMP-01355 | E12: dutyStationCountyCode | F12: FIELD | G12: STRUCTURAL | H12: MAX_LENGTH | I12: dutyStationCountyCode must not exceed 8 characters. | J12: `dutyStationCountyCode` IS NULL OR (length(`dutyStationCountyCode`) <= 8) | K12: `dutyStationCountyCode` IS NULL OR length(cast(`dutyStationCountyCode` as string)) <= 8 /* schema:optional, valid:no_match, datafiles:match, db:column_match */ | baseline: `dutyStationCountyCode` IS NULL OR (length(`dutyStationCountyCode`) <= 8) | L12: SQL READY | M12: VALIDATED | O12: string | P12: ≤ 8 characters | S12: Schema-aligned candidate | T12: 3-character FIPS county code parsed from positions 3-5 of the 9-character OPM Duty Station composite code. 000=not in county. VA: 013=Arlington. 059=Fairfax. MD: 031=Montgomery.; Schema-aligned structural validation; raw JSON Schema validation occurs before Spark parsing. | U12: Data Files Excel candidate; Approved Employment JSON contract | V12: Data Files07102026.xlsx::Employment!row 45; User-provided Employment JSON Schema/common definitions
A13: SmartDEV | B13: Employment | C13: VAL-01351 | D13: ERR-EMP-01351 | E13: dutyStationStateCode | F13: FIELD | G13: STRUCTURAL | H13: DATA_TYPE | I13: dutyStationStateCode must match JSON Schema type string or null. | J13: `dutyStationStateCode` IS NULL OR (typeof(`dutyStationStateCode`) = 'string') | K13: `dutyStationStateCode` IS NULL OR typeof(`dutyStationStateCode`) = 'string' /* schema:optional, valid:no_match, datafiles:match, db:column_match */ | baseline: `dutyStationStateCode` IS NULL OR (typeof(`dutyStationStateCode`) = 'string') | L13: HANDLED IN JSON VALIDATION | M13: VALIDATED | O13: string | P13: ≤ 8 characters | S13: Schema-aligned candidate | T13: 2-character FIPS state code parsed from positions 1-2 of the 9-character OPM Duty Station composite code, identifying the state of the employee's official worksite. 01=AL. 06=CA. 11=DC. 24=MD. 51=VA. 72=PR.; Schema-aligned structural validation; raw JSON Schema validation occurs before Spark parsing. | U13: Data Files Excel candidate; Approved Employment JSON contract | V13: Data Files07102026.xlsx::Employment!row 44; User-provided Employment JSON Schema/common definitions
A14: SmartDEV | B14: Employment | C14: VAL-01352 | D14: ERR-EMP-01352 | E14: dutyStationStateCode | F14: FIELD | G14: STRUCTURAL | H14: MAX_LENGTH | I14: dutyStationStateCode must not exceed 8 characters. | J14: `dutyStationStateCode` IS NULL OR (length(`dutyStationStateCode`) <= 8) | K14: `dutyStationStateCode` IS NULL OR length(cast(`dutyStationStateCode` as string)) <= 8 /* schema:optional, valid:no_match, datafiles:match, db:column_match */ | baseline: `dutyStationStateCode` IS NULL OR (length(`dutyStationStateCode`) <= 8) | L14: SQL READY | M14: VALIDATED | O14: string | P14: ≤ 8 characters | S14: Schema-aligned candidate | T14: 2-character FIPS state code parsed from positions 1-2 of the 9-character OPM Duty Station composite code, identifying the state of the employee's official worksite. 01=AL. 06=CA. 11=DC. 24=MD. 51=VA. 72=PR.; Schema-aligned structural validation; raw JSON Schema validation occurs before Spark parsing. | U14: Data Files Excel candidate; Approved Employment JSON contract | V14: Data Files07102026.xlsx::Employment!row 44; User-provided Employment JSON Schema/common definitions
A15: SmartDEV | B15: Employment | C15: VAL-01282 | D15: ERR-EMP-01282 | E15: effectiveDate | F15: FIELD | G15: STRUCTURAL | H15: REQUIRED | I15: effectiveDate is required and must not be blank. | J15: `effectiveDate` IS NOT NULL AND trim(`effectiveDate`) <> '' | K15: `effectiveDate` IS NOT NULL AND trim(cast(`effectiveDate` as string)) <> '' /* schema:required, valid:field_match, datafiles:match, db:column_match */ | baseline: `effectiveDate` IS NOT NULL AND trim(`effectiveDate`) <> '' | L15: HANDLED IN JSON VALIDATION | M15: VALIDATED | O15: string (date) | Q15: mm/dd/yyyy | S15: Schema-aligned candidate | T15: Represents the as of date for any action taken on employment. For example, if an employee went to leave, the effective date represents the begin date of the leave status; when employee returns to work, the effective date of the active status row minus a day becomes the leave status end date. This must be entered for new hires, re-hires, or changes in Contribution Groups or Position Status (for example, from nonparticipating Law Enforcement Officer to contributing Law Enforcement Officer, or from contributing Bus Driver to contributing Teacher.) Please pay special attention to re-hires; submit the employment date the employee is re-hired (the most recent employment date). For employees who are changing Contribution Groups within the same position (e.g., from non-participating Law Enforcement Officer to contributing Law Enforcement Officer), the date should reflect the date the employee began in the new Contribution Group. If reporting any other change in Contribution Group (e.g., due to a change in position status), report the date the position status changed. Report the as of date when the employee is terminated or when the employee’s Contribution Group or Position Status changes due to a change in position. Pertaining to death, this should reflect the date the employee passed away.; Schema-aligned structural validation; raw JSON Schema validation occurs before Spark parsing. | U15: Data Files Excel candidate; Approved Employment JSON contract | V15: Data Files07102026.xlsx::Employment!row 21; User-provided Employment JSON Schema/common definitions
A16: SmartDEV | B16: Employment | C16: VAL-01283 | D16: ERR-EMP-01283 | E16: effectiveDate | F16: FIELD | G16: STRUCTURAL | H16: DATA_TYPE | I16: effectiveDate must match JSON Schema type string and format yyyy-MM-dd. | J16: `effectiveDate` IS NULL OR (typeof(`effectiveDate`) = 'string') | K16: `effectiveDate` IS NULL OR to_date(cast(`effectiveDate` as string), 'yyyy-MM-dd') IS NOT NULL /* schema:required, valid:field_match, datafiles:match, db:column_match */ | baseline: `effectiveDate` IS NULL OR (typeof(`effectiveDate`) = 'string') | L16: HANDLED IN JSON VALIDATION | M16: VALIDATED | O16: string (date) | Q16: mm/dd/yyyy | S16: Schema-aligned candidate | T16: Represents the as of date for any action taken on employment. For example, if an employee went to leave, the effective date represents the begin date of the leave status; when employee returns to work, the effective date of the active status row minus a day becomes the leave status end date. This must be entered for new hires, re-hires, or changes in Contribution Groups or Position Status (for example, from nonparticipating Law Enforcement Officer to contributing Law Enforcement Officer, or from contributing Bus Driver to contributing Teacher.) Please pay special attention to re-hires; submit the employment date the employee is re-hired (the most recent employment date). For employees who are changing Contribution Groups within the same position (e.g., from non-participating Law Enforcement Officer to contributing Law Enforcement Officer), the date should reflect the date the employee began in the new Contribution Group. If reporting any other change in Contribution Group (e.g., due to a change in position status), report the date the position status changed. Report the as of date when the employee is terminated or when the employee’s Contribution Group or Position Status changes due to a change in position. Pertaining to death, this should reflect the date the employee passed away.; Schema-aligned structural validation; raw JSON Schema validation occurs before Spark parsing. | U16: Data Files Excel candidate; Approved Employment JSON contract | V16: Data Files07102026.xlsx::Employment!row 21; User-provided Employment JSON Schema/common definitions
A17: SmartDEV | B17: Employment | C17: VAL-01271 | D17: ERR-EMP-01271 | E17: employeeUniqueId | F17: FIELD | G17: STRUCTURAL | H17: REQUIRED | I17: employeeUniqueId is required and must not be blank. | J17: `employeeUniqueId` IS NOT NULL AND trim(`employeeUniqueId`) <> '' | K17: `employeeUniqueId` IS NOT NULL AND trim(cast(`employeeUniqueId` as string)) <> '' /* schema:required, valid:no_match, datafiles:check, db:column_match */ | baseline: `employeeUniqueId` IS NOT NULL AND trim(`employeeUniqueId`) <> '' | L17: HANDLED IN JSON VALIDATION | M17: VALIDATED | O17: string | P17: 1-64 characters | Q17: 123456 | S17: Schema-aligned candidate | T17: Primary participant identifier; this could be the SSN or Employee Id to be determined by the project team.; Schema-aligned structural validation; raw JSON Schema validation occurs before Spark parsing. | U17: Data Files Excel candidate; Approved Employment JSON contract | V17: Data Files07102026.xlsx::Employment!row 17; User-provided Employment JSON Schema/common definitions
A18: SmartDEV | B18: Employment | C18: VAL-01272 | D18: ERR-EMP-01272 | E18: employeeUniqueId | F18: FIELD | G18: STRUCTURAL | H18: DATA_TYPE | I18: employeeUniqueId must match JSON Schema type string. | J18: `employeeUniqueId` IS NULL OR (typeof(`employeeUniqueId`) = 'string') | K18: `employeeUniqueId` IS NULL OR typeof(`employeeUniqueId`) = 'string' /* schema:required, valid:no_match, datafiles:check, db:column_match */ | baseline: `employeeUniqueId` IS NULL OR (typeof(`employeeUniqueId`) = 'string') | L18: HANDLED IN JSON VALIDATION | M18: VALIDATED | O18: string | P18: 1-64 characters | Q18: 123456 | S18: Schema-aligned candidate | T18: Primary participant identifier; this could be the SSN or Employee Id to be determined by the project team.; Schema-aligned structural validation; raw JSON Schema validation occurs before Spark parsing. | U18: Data Files Excel candidate; Approved Employment JSON contract | V18: Data Files07102026.xlsx::Employment!row 17; User-provided Employment JSON Schema/common definitions
A19: SmartDEV | B19: Employment | C19: VAL-11272 | D19: ERR-EMP-11272 | E19: employeeUniqueId | F19: FIELD | G19: STRUCTURAL | H19: PATTERN | I19: employeeUniqueId must match JSON Schema type pattern. | J19: `employeeUniqueId` IS NULL OR (trim(`employeeUniqueId`) RLIKE '^[A-Za-z0-9._:-]{1,64}$') | K19: `employeeUniqueId` IS NULL OR typeof(`employeeUniqueId`) = 'string' /* schema:required, valid:no_match, datafiles:check, db:column_match */ | baseline: `employeeUniqueId` IS NULL OR (typeof(`employeeUniqueId`) = 'string') | L19: HANDLED IN JSON VALIDATION | M19: VALIDATED | O19: string | P19: 1-64 characters | Q19: 123456 | S19: Schema-aligned candidate | T19: Primary participant identifier; this could be the SSN or Employee Id to be determined by the project team.; Schema-aligned structural validation; raw JSON Schema validation occurs before Spark parsing. | U19: Data Files Excel candidate; Approved Employment JSON contract | V19: Data Files07102026.xlsx::Employment!row 17; User-provided Employment JSON Schema/common definitions
A20: SmartDEV | B20: Employment | C20: VAL-00029 | D20: ERR-EMP-00029 | E20: employerCode | F20: FIELD | G20: STRUCTURAL | H20: REQUIRED | I20: employerCode is required and must not be blank. | J20: `employerCode` IS NOT NULL AND trim(`employerCode`) <> '' | K20: `employerCode` IS NOT NULL AND trim(cast(`employerCode` as string)) <> '' /* schema:required, valid:field_match, datafiles:match, db:column_match */ | baseline: `employerCode` IS NOT NULL AND trim(`employerCode`) <> '' | L20: HANDLED IN JSON VALIDATION | M20: VALIDATED | O20: string | P20: 1-4 characters | Q20: ^[A-Za-z0-9]{1,4}$ | S20: Schema-aligned candidate | T20: Required in the Employment JSON payload. Datatype, length, pattern, and future allowed-value checks are maintained as separate validation rows.; Schema-aligned structural validation; raw JSON Schema validation occurs before Spark parsing. | U20: Current implemented L1 config; Approved Employment JSON contract | V20: common-definitions.schema.json#/$defs/employerCode; structural_rules.yaml via Current L1 Config; User-provided Employment JSON Schema/common definitions
A21: SmartDEV | B21: Employment | C21: VAL-01238 | D21: ERR-EMP-01238 | E21: employerCode | F21: FIELD | G21: STRUCTURAL | H21: DATA_TYPE | I21: employerCode must be a JSON string. | J21: `employerCode` IS NULL OR (typeof(`employerCode`) = 'string') | K21: `employerCode` IS NULL OR typeof(`employerCode`) = 'string' /* schema:required, valid:field_match, datafiles:match, db:column_match */ | baseline: `employerCode` IS NULL OR (typeof(`employerCode`) = 'string') | L21: HANDLED IN JSON VALIDATION | M21: VALIDATED | O21: string | P21: 1-4 characters | Q21: ^[A-Za-z0-9]{1,4}$ | S21: Schema-aligned candidate | T21: Payload-level datatype validation. Duplicate header/footer datatype rules were merged into this retained Validation ID.; Schema-aligned structural validation; raw JSON Schema validation occurs before Spark parsing. | U21: Data Files Excel candidate; Approved Employment JSON contract | V21: common-definitions.schema.json#/$defs/employerCode; Data Files07102026.xlsx::Employment!row 6; User-provided Employment JSON Schema/common definitions
A22: SmartDEV | B22: Employment | C22: VAL-01239 | D22: ERR-EMP-01239 | E22: employerCode | F22: FIELD | G22: STRUCTURAL | H22: MAX_LENGTH | I22: employerCode must not exceed 4 characters. | J22: `employerCode` IS NULL OR (length(`employerCode`) <= 4) | K22: `employerCode` IS NULL OR length(cast(`employerCode` as string)) <= 1 /* schema:required, valid:field_match, datafiles:match, db:column_match */ | baseline: `employerCode` IS NULL OR (length(`employerCode`) <= 4) | L22: SQL READY | M22: VALIDATED | O22: string | P22: 1-4 characters | Q22: ^[A-Za-z0-9]{1,4}$ | S22: Schema-aligned candidate | T22: Payload-level length validation. Duplicate header/footer length rules were merged into this retained Validation ID.; Schema-aligned structural validation; raw JSON Schema validation occurs before Spark parsing. | U22: Data Files Excel candidate; Approved Employment JSON contract | V22: common-definitions.schema.json#/$defs/employerCode; Data Files07102026.xlsx::Employment!row 6; User-provided Employment JSON Schema/common definitions
A23: SmartDEV | B23: Employment | C23: VAL-02940 | D23: ERR-EMP-02940 | E23: employerCode | F23: FIELD | G23: STRUCTURAL | H23: PATTERN | I23: employerCode must match ^[A-Za-z0-9]{1,4}$. | J23: `employerCode` IS NULL OR (`employerCode` RLIKE '^[A-Za-z0-9]{1,4}$') | K23: `employerCode` IS NULL OR (`employerCode` RLIKE '^[A-Za-z0-9]{1,4}$') /* schema:required, valid:field_match, datafiles:match, db:column_match */ | L23: SQL READY | M23: VALIDATED | O23: string | P23: 1-4 characters | Q23: ^[A-Za-z0-9]{1,4}$ | S23: Schema-aligned candidate | T23: Separate payload-level character-pattern validation added from the JSON common definition.; Schema-aligned structural validation; raw JSON Schema validation occurs before Spark parsing. | U23: Common definition constraint; Approved Employment JSON contract | V23: common-definitions.schema.json#/$defs/employerCode; User-provided Employment JSON Schema/common definitions
A24: SmartDEV | B24: Employment | C24: VAL-01321 | D24: ERR-EMP-01321 | E24: exempt | F24: FIELD | G24: STRUCTURAL | H24: DATA_TYPE | I24: exempt must match JSON Schema type boolean or null. | J24: `exempt` IS NULL OR (typeof(`exempt`) = 'boolean') | K24: `exempt` IS NULL OR upper(trim(cast(`exempt` as string))) IN ('Y','N','TRUE','FALSE','1','0') /* schema:optional, valid:no_match, datafiles:match, db:column_match */ | baseline: `exempt` IS NULL OR (typeof(`exempt`) = 'boolean') | L24: HANDLED IN JSON VALIDATION | M24: VALIDATED | O24: boolean | S24: Schema-aligned candidate | T24: Represents the exempt indicator of an employee. From an employment/payroll perspective, “exempt” usually means an employee is exempt from (not covered by) certain wage-and-hour rules—most notably the overtime pay requirements of the Fair Labor Standards Act (FLSA) in the U.S.; Schema-aligned structural validation; raw JSON Schema validation occurs before Spark parsing. | U24: Data Files Excel candidate; Approved Employment JSON contract | V24: Data Files07102026.xlsx::Employment!row 33; User-provided Employment JSON Schema/common definitions
A25: SmartDEV | B25: Employment | C25: VAL-01324 | D25: ERR-EMP-01324 | E25: exempt2 | F25: FIELD | G25: STRUCTURAL | H25: DATA_TYPE | I25: exempt2 must match JSON Schema type string or null. | J25: `exempt2` IS NULL OR (typeof(`exempt2`) = 'string') | K25: `exempt2` IS NULL OR typeof(`exempt2`) = 'string' /* schema:optional, valid:no_match, datafiles:match, db:check_mapping */ | baseline: `exempt2` IS NULL OR (typeof(`exempt2`) = 'string') | L25: HANDLED IN JSON VALIDATION | M25: VALIDATED | O25: string | P25: ≤ 8 characters | S25: Schema-aligned candidate | T25: Schema-aligned structural validation; raw JSON Schema validation occurs before Spark parsing. | U25: Data Files Excel candidate; Approved Employment JSON contract | V25: Data Files07102026.xlsx::Employment!row 34; User-provided Employment JSON Schema/common definitions
A26: SmartDEV | B26: Employment | C26: VAL-01325 | D26: ERR-EMP-01325 | E26: exempt2 | F26: FIELD | G26: STRUCTURAL | H26: MAX_LENGTH | I26: exempt2 must not exceed 8 characters. | J26: `exempt2` IS NULL OR (length(`exempt2`) <= 8) | K26: `exempt2` IS NULL OR length(cast(`exempt2` as string)) <= 8 /* schema:optional, valid:no_match, datafiles:match, db:check_mapping */ | baseline: `exempt2` IS NULL OR (length(`exempt2`) <= 8) | L26: SQL READY | M26: VALIDATED | O26: string | P26: ≤ 8 characters | S26: Schema-aligned candidate | T26: Schema-aligned structural validation; raw JSON Schema validation occurs before Spark parsing. | U26: Data Files Excel candidate; Approved Employment JSON contract | V26: Data Files07102026.xlsx::Employment!row 34; User-provided Employment JSON Schema/common definitions
A27: SmartDEV | B27: Employment | C27: VAL-01326 | D27: ERR-EMP-01326 | E27: exempt3 | F27: FIELD | G27: STRUCTURAL | H27: DATA_TYPE | I27: exempt3 must match JSON Schema type string or null. | J27: `exempt3` IS NULL OR (typeof(`exempt3`) = 'string') | K27: `exempt3` IS NULL OR typeof(`exempt3`) = 'string' /* schema:optional, valid:no_match, datafiles:match, db:check_mapping */ | baseline: `exempt3` IS NULL OR (typeof(`exempt3`) = 'string') | L27: HANDLED IN JSON VALIDATION | M27: VALIDATED | O27: string | P27: ≤ 8 characters | S27: Schema-aligned candidate | T27: Schema-aligned structural validation; raw JSON Schema validation occurs before Spark parsing. | U27: Data Files Excel candidate; Approved Employment JSON contract | V27: Data Files07102026.xlsx::Employment!row 35; User-provided Employment JSON Schema/common definitions
